[2024-05-27T05:03:07.884+0000] {local_task_job_runner.py:120} INFO - ::group::Pre task execution logs
[2024-05-27T05:03:07.914+0000] {taskinstance.py:2076} INFO - Dependencies all met for dep_context=non-requeueable deps ti=<TaskInstance: bigquery_example.run_bigquery_query manual__2024-05-27T05:02:55.286693+00:00 [queued]>
[2024-05-27T05:03:07.932+0000] {taskinstance.py:2076} INFO - Dependencies all met for dep_context=requeueable deps ti=<TaskInstance: bigquery_example.run_bigquery_query manual__2024-05-27T05:02:55.286693+00:00 [queued]>
[2024-05-27T05:03:07.934+0000] {taskinstance.py:2306} INFO - Starting attempt 1 of 2
[2024-05-27T05:03:07.958+0000] {taskinstance.py:2330} INFO - Executing <Task(BigQueryInsertJobOperator): run_bigquery_query> on 2024-05-27 05:02:55.286693+00:00
[2024-05-27T05:03:07.975+0000] {warnings.py:110} WARNING - /home/***/.local/lib/python3.12/site-packages/***/task/task_runner/standard_task_runner.py:61: DeprecationWarning: This process (pid=78) is multi-threaded, use of fork() may lead to deadlocks in the child.
  pid = os.fork()

[2024-05-27T05:03:07.979+0000] {standard_task_runner.py:63} INFO - Started process 80 to run task
[2024-05-27T05:03:07.979+0000] {standard_task_runner.py:90} INFO - Running: ['***', 'tasks', 'run', 'bigquery_example', 'run_bigquery_query', 'manual__2024-05-27T05:02:55.286693+00:00', '--job-id', '60', '--raw', '--subdir', 'DAGS_FOLDER/test.py', '--cfg-path', '/tmp/tmp4gmu5eck']
[2024-05-27T05:03:07.983+0000] {standard_task_runner.py:91} INFO - Job 60: Subtask run_bigquery_query
[2024-05-27T05:03:08.076+0000] {task_command.py:426} INFO - Running <TaskInstance: bigquery_example.run_bigquery_query manual__2024-05-27T05:02:55.286693+00:00 [running]> on host fed9f026ca00
[2024-05-27T05:03:08.237+0000] {taskinstance.py:2648} INFO - Exporting env vars: AIRFLOW_CTX_DAG_OWNER='nquynh' AIRFLOW_CTX_DAG_ID='bigquery_example' AIRFLOW_CTX_TASK_ID='run_bigquery_query' AIRFLOW_CTX_EXECUTION_DATE='2024-05-27T05:02:55.286693+00:00' AIRFLOW_CTX_TRY_NUMBER='1' AIRFLOW_CTX_DAG_RUN_ID='manual__2024-05-27T05:02:55.286693+00:00'
[2024-05-27T05:03:08.239+0000] {taskinstance.py:430} INFO - ::endgroup::
[2024-05-27T05:03:08.306+0000] {connection.py:274} WARNING - Connection schemes (type: google_cloud_platform) shall not contain '_' according to RFC3986.
[2024-05-27T05:03:08.313+0000] {base.py:84} INFO - Using connection ID 'google_cloud_default' for task execution.
[2024-05-27T05:03:08.315+0000] {taskinstance.py:441} INFO - ::group::Post task execution logs
[2024-05-27T05:03:08.316+0000] {taskinstance.py:2905} ERROR - Task failed with exception
Traceback (most recent call last):
  File "/home/airflow/.local/lib/python3.12/site-packages/airflow/models/taskinstance.py", line 465, in _execute_task
    result = _execute_callable(context=context, **execute_callable_kwargs)
             ^^^^^^^^^^^^^^^^^^^^^^^^^^^^^^^^^^^^^^^^^^^^^^^^^^^^^^^^^^^^^
  File "/home/airflow/.local/lib/python3.12/site-packages/airflow/models/taskinstance.py", line 432, in _execute_callable
    return execute_callable(context=context, **execute_callable_kwargs)
           ^^^^^^^^^^^^^^^^^^^^^^^^^^^^^^^^^^^^^^^^^^^^^^^^^^^^^^^^^^^^
  File "/home/airflow/.local/lib/python3.12/site-packages/airflow/models/baseoperator.py", line 400, in wrapper
    return func(self, *args, **kwargs)
           ^^^^^^^^^^^^^^^^^^^^^^^^^^^
  File "/home/airflow/.local/lib/python3.12/site-packages/airflow/providers/google/cloud/operators/bigquery.py", line 2820, in execute
    self.project_id = hook.project_id
                      ^^^^^^^^^^^^^^^
  File "/home/airflow/.local/lib/python3.12/site-packages/airflow/providers/google/common/hooks/base_google.py", line 373, in project_id
    _, project_id = self.get_credentials_and_project_id()
                    ^^^^^^^^^^^^^^^^^^^^^^^^^^^^^^^^^^^^^
  File "/home/airflow/.local/lib/python3.12/site-packages/airflow/providers/google/common/hooks/base_google.py", line 285, in get_credentials_and_project_id
    credentials, project_id = get_credentials_and_project_id(
                              ^^^^^^^^^^^^^^^^^^^^^^^^^^^^^^^
  File "/home/airflow/.local/lib/python3.12/site-packages/airflow/providers/google/cloud/utils/credentials_provider.py", line 362, in get_credentials_and_project_id
    return _CredentialProvider(*args, **kwargs).get_credentials_and_project()
           ^^^^^^^^^^^^^^^^^^^^^^^^^^^^^^^^^^^^^^^^^^^^^^^^^^^^^^^^^^^^^^^^^^
  File "/home/airflow/.local/lib/python3.12/site-packages/airflow/providers/google/cloud/utils/credentials_provider.py", line 235, in get_credentials_and_project
    credentials, project_id = self._get_credentials_using_key_path()
                              ^^^^^^^^^^^^^^^^^^^^^^^^^^^^^^^^^^^^^^
  File "/home/airflow/.local/lib/python3.12/site-packages/airflow/providers/google/cloud/utils/credentials_provider.py", line 286, in _get_credentials_using_key_path
    credentials = google.oauth2.service_account.Credentials.from_service_account_file(
                  ^^^^^^^^^^^^^^^^^^^^^^^^^^^^^^^^^^^^^^^^^^^^^^^^^^^^^^^^^^^^^^^^^^^^
  File "/home/airflow/.local/lib/python3.12/site-packages/google/oauth2/service_account.py", line 258, in from_service_account_file
    info, signer = _service_account_info.from_filename(
                   ^^^^^^^^^^^^^^^^^^^^^^^^^^^^^^^^^^^^
  File "/home/airflow/.local/lib/python3.12/site-packages/google/auth/_service_account_info.py", line 78, in from_filename
    with io.open(filename, "r", encoding="utf-8") as json_file:
         ^^^^^^^^^^^^^^^^^^^^^^^^^^^^^^^^^^^^^^^^
PermissionError: [Errno 13] Permission denied: '/root/airflow/config/gcloud_service_key.json'
[2024-05-27T05:03:08.360+0000] {taskinstance.py:1206} INFO - Marking task as UP_FOR_RETRY. dag_id=bigquery_example, task_id=run_bigquery_query, run_id=manual__2024-05-27T05:02:55.286693+00:00, execution_date=20240527T050255, start_date=20240527T050307, end_date=20240527T050308
[2024-05-27T05:03:08.423+0000] {standard_task_runner.py:110} ERROR - Failed to execute job 60 for task run_bigquery_query ([Errno 13] Permission denied: '/root/airflow/config/gcloud_service_key.json'; 80)
[2024-05-27T05:03:08.478+0000] {local_task_job_runner.py:240} INFO - Task exited with return code 1
[2024-05-27T05:03:08.538+0000] {taskinstance.py:3498} INFO - 0 downstream tasks scheduled from follow-on schedule check
[2024-05-27T05:03:08.542+0000] {local_task_job_runner.py:222} INFO - ::endgroup::
