[2024-05-28T09:23:50.545+0000] {local_task_job_runner.py:120} INFO - ::group::Pre task execution logs
[2024-05-28T09:23:50.579+0000] {taskinstance.py:2076} INFO - Dependencies all met for dep_context=non-requeueable deps ti=<TaskInstance: oltp_to_olap_all_transform.create_Sale_Table manual__2024-05-28T09:22:38.757554+00:00 [queued]>
[2024-05-28T09:23:50.598+0000] {taskinstance.py:2076} INFO - Dependencies all met for dep_context=requeueable deps ti=<TaskInstance: oltp_to_olap_all_transform.create_Sale_Table manual__2024-05-28T09:22:38.757554+00:00 [queued]>
[2024-05-28T09:23:50.599+0000] {taskinstance.py:2306} INFO - Starting attempt 1 of 0
[2024-05-28T09:23:50.622+0000] {taskinstance.py:2330} INFO - Executing <Task(BigQueryInsertJobOperator): create_Sale_Table> on 2024-05-28 09:22:38.757554+00:00
[2024-05-28T09:23:50.631+0000] {warnings.py:110} WARNING - /home/***/.local/lib/python3.12/site-packages/***/task/task_runner/standard_task_runner.py:61: DeprecationWarning: This process (pid=1012) is multi-threaded, use of fork() may lead to deadlocks in the child.
  pid = os.fork()

[2024-05-28T09:23:50.634+0000] {standard_task_runner.py:63} INFO - Started process 1014 to run task
[2024-05-28T09:23:50.634+0000] {standard_task_runner.py:90} INFO - Running: ['***', 'tasks', 'run', 'oltp_to_olap_all_transform', 'create_Sale_Table', 'manual__2024-05-28T09:22:38.757554+00:00', '--job-id', '245', '--raw', '--subdir', 'DAGS_FOLDER/oltp_olap.py', '--cfg-path', '/tmp/tmp7svphav3']
[2024-05-28T09:23:50.638+0000] {standard_task_runner.py:91} INFO - Job 245: Subtask create_Sale_Table
[2024-05-28T09:23:50.713+0000] {task_command.py:426} INFO - Running <TaskInstance: oltp_to_olap_all_transform.create_Sale_Table manual__2024-05-28T09:22:38.757554+00:00 [running]> on host 9b03efc10d80
[2024-05-28T09:23:50.851+0000] {taskinstance.py:2648} INFO - Exporting env vars: AIRFLOW_CTX_DAG_OWNER='ngquynh' AIRFLOW_CTX_DAG_ID='oltp_to_olap_all_transform' AIRFLOW_CTX_TASK_ID='create_Sale_Table' AIRFLOW_CTX_EXECUTION_DATE='2024-05-28T09:22:38.757554+00:00' AIRFLOW_CTX_TRY_NUMBER='1' AIRFLOW_CTX_DAG_RUN_ID='manual__2024-05-28T09:22:38.757554+00:00'
[2024-05-28T09:23:50.854+0000] {taskinstance.py:430} INFO - ::endgroup::
[2024-05-28T09:23:50.884+0000] {connection.py:274} WARNING - Connection schemes (type: google_cloud_platform) shall not contain '_' according to RFC3986.
[2024-05-28T09:23:50.888+0000] {base.py:84} INFO - Using connection ID 'google_cloud_default' for task execution.
[2024-05-28T09:23:50.959+0000] {bigquery.py:2832} INFO - Executing: {'query': {'query': 'CREATE TABLE `datawarehouse-423912.OLAP_dataset.Sale_table` AS\nSELECT \n    orderID,\n    SUM(quantity * unitprice * (1 - discount)) AS total_revenue\nFROM \n    `datawarehouse-423912.OLAP_dataset.Dim_Order_details`\nGROUP BY \n    orderID;', 'useLegacySql': False}}'
[2024-05-28T09:23:50.964+0000] {bigquery.py:1660} INFO - Inserting job ***_oltp_to_olap_all_transform_create_Sale_Table_2024_05_28T09_22_38_757554_00_00_b34611ce4d61f33916b58d356f3d5662
[2024-05-28T09:24:05.175+0000] {taskinstance.py:441} INFO - ::group::Post task execution logs
[2024-05-28T09:24:05.176+0000] {taskinstance.py:2905} ERROR - Task failed with exception
Traceback (most recent call last):
  File "/home/airflow/.local/lib/python3.12/site-packages/airflow/models/taskinstance.py", line 465, in _execute_task
    result = _execute_callable(context=context, **execute_callable_kwargs)
             ^^^^^^^^^^^^^^^^^^^^^^^^^^^^^^^^^^^^^^^^^^^^^^^^^^^^^^^^^^^^^
  File "/home/airflow/.local/lib/python3.12/site-packages/airflow/models/taskinstance.py", line 432, in _execute_callable
    return execute_callable(context=context, **execute_callable_kwargs)
           ^^^^^^^^^^^^^^^^^^^^^^^^^^^^^^^^^^^^^^^^^^^^^^^^^^^^^^^^^^^^
  File "/home/airflow/.local/lib/python3.12/site-packages/airflow/models/baseoperator.py", line 400, in wrapper
    return func(self, *args, **kwargs)
           ^^^^^^^^^^^^^^^^^^^^^^^^^^^
  File "/home/airflow/.local/lib/python3.12/site-packages/airflow/providers/google/cloud/operators/bigquery.py", line 2891, in execute
    job.result(timeout=self.result_timeout, retry=self.result_retry)
  File "/home/airflow/.local/lib/python3.12/site-packages/google/cloud/bigquery/job/query.py", line 1626, in result
    while not is_job_done():
              ^^^^^^^^^^^^^
  File "/home/airflow/.local/lib/python3.12/site-packages/google/cloud/bigquery/job/query.py", line 1577, in is_job_done
    raise job_failed_exception
google.api_core.exceptions.Conflict: 409 Already Exists: Table datawarehouse-423912:OLAP_dataset.Sale_table; reason: duplicate, message: Already Exists: Table datawarehouse-423912:OLAP_dataset.Sale_table

Location: US
Job ID: airflow_oltp_to_olap_all_transform_create_Sale_Table_2024_05_28T09_22_38_757554_00_00_b34611ce4d61f33916b58d356f3d5662

[2024-05-28T09:24:05.195+0000] {taskinstance.py:1206} INFO - Marking task as FAILED. dag_id=oltp_to_olap_all_transform, task_id=create_Sale_Table, run_id=manual__2024-05-28T09:22:38.757554+00:00, execution_date=20240528T092238, start_date=20240528T092350, end_date=20240528T092405
[2024-05-28T09:24:05.218+0000] {standard_task_runner.py:110} ERROR - Failed to execute job 245 for task create_Sale_Table (409 Already Exists: Table datawarehouse-423912:OLAP_dataset.Sale_table; reason: duplicate, message: Already Exists: Table datawarehouse-423912:OLAP_dataset.Sale_table

Location: US
Job ID: airflow_oltp_to_olap_all_transform_create_Sale_Table_2024_05_28T09_22_38_757554_00_00_b34611ce4d61f33916b58d356f3d5662
; 1014)
[2024-05-28T09:24:05.255+0000] {local_task_job_runner.py:240} INFO - Task exited with return code 1
[2024-05-28T09:24:05.297+0000] {taskinstance.py:3498} INFO - 0 downstream tasks scheduled from follow-on schedule check
[2024-05-28T09:24:05.305+0000] {local_task_job_runner.py:222} INFO - ::endgroup::
