[2024-05-28T04:58:49.333+0000] {local_task_job_runner.py:120} INFO - ::group::Pre task execution logs
[2024-05-28T04:58:49.369+0000] {taskinstance.py:2076} INFO - Dependencies all met for dep_context=non-requeueable deps ti=<TaskInstance: oltp_to_olap_all_transform.load_dim_customer manual__2024-05-28T04:58:24.100726+00:00 [queued]>
[2024-05-28T04:58:49.387+0000] {taskinstance.py:2076} INFO - Dependencies all met for dep_context=requeueable deps ti=<TaskInstance: oltp_to_olap_all_transform.load_dim_customer manual__2024-05-28T04:58:24.100726+00:00 [queued]>
[2024-05-28T04:58:49.388+0000] {taskinstance.py:2306} INFO - Starting attempt 1 of 0
[2024-05-28T04:58:49.418+0000] {taskinstance.py:2330} INFO - Executing <Task(BigQueryInsertJobOperator): load_dim_customer> on 2024-05-28 04:58:24.100726+00:00
[2024-05-28T04:58:49.436+0000] {warnings.py:110} WARNING - /home/***/.local/lib/python3.12/site-packages/***/task/task_runner/standard_task_runner.py:61: DeprecationWarning: This process (pid=329) is multi-threaded, use of fork() may lead to deadlocks in the child.
  pid = os.fork()

[2024-05-28T04:58:49.443+0000] {standard_task_runner.py:63} INFO - Started process 331 to run task
[2024-05-28T04:58:49.443+0000] {standard_task_runner.py:90} INFO - Running: ['***', 'tasks', 'run', 'oltp_to_olap_all_transform', 'load_dim_customer', 'manual__2024-05-28T04:58:24.100726+00:00', '--job-id', '128', '--raw', '--subdir', 'DAGS_FOLDER/oltp_olap.py', '--cfg-path', '/tmp/tmpp3j0bf47']
[2024-05-28T04:58:49.451+0000] {standard_task_runner.py:91} INFO - Job 128: Subtask load_dim_customer
[2024-05-28T04:58:49.655+0000] {task_command.py:426} INFO - Running <TaskInstance: oltp_to_olap_all_transform.load_dim_customer manual__2024-05-28T04:58:24.100726+00:00 [running]> on host 9b03efc10d80
[2024-05-28T04:58:49.981+0000] {taskinstance.py:2648} INFO - Exporting env vars: AIRFLOW_CTX_DAG_OWNER='ngquynh' AIRFLOW_CTX_DAG_ID='oltp_to_olap_all_transform' AIRFLOW_CTX_TASK_ID='load_dim_customer' AIRFLOW_CTX_EXECUTION_DATE='2024-05-28T04:58:24.100726+00:00' AIRFLOW_CTX_TRY_NUMBER='1' AIRFLOW_CTX_DAG_RUN_ID='manual__2024-05-28T04:58:24.100726+00:00'
[2024-05-28T04:58:49.985+0000] {taskinstance.py:430} INFO - ::endgroup::
[2024-05-28T04:58:50.031+0000] {connection.py:274} WARNING - Connection schemes (type: google_cloud_platform) shall not contain '_' according to RFC3986.
[2024-05-28T04:58:50.036+0000] {base.py:84} INFO - Using connection ID 'google_cloud_default' for task execution.
[2024-05-28T04:58:50.133+0000] {bigquery.py:2832} INFO - Executing: {'query': {'query': 'create or replace table `datawarehouse-423912.OLAP_dataset.Dim_customer` as\nselect \ncustomerID,\ncontactName,\naddress,\ncity,\nphone,\ncountry\nfrom\n`datawarehouse-423912.warehouse.customers`', 'useLegacySql': False}}'
[2024-05-28T04:58:50.136+0000] {bigquery.py:1660} INFO - Inserting job ***_oltp_to_olap_all_transform_load_dim_customer_2024_05_28T04_58_24_100726_00_00_9bf3a521e19fa6f1fcfd01aa42cddc81
[2024-05-28T04:58:51.983+0000] {taskinstance.py:441} INFO - ::group::Post task execution logs
[2024-05-28T04:58:51.987+0000] {taskinstance.py:2905} ERROR - Task failed with exception
Traceback (most recent call last):
  File "/home/airflow/.local/lib/python3.12/site-packages/airflow/models/taskinstance.py", line 465, in _execute_task
    result = _execute_callable(context=context, **execute_callable_kwargs)
             ^^^^^^^^^^^^^^^^^^^^^^^^^^^^^^^^^^^^^^^^^^^^^^^^^^^^^^^^^^^^^
  File "/home/airflow/.local/lib/python3.12/site-packages/airflow/models/taskinstance.py", line 432, in _execute_callable
    return execute_callable(context=context, **execute_callable_kwargs)
           ^^^^^^^^^^^^^^^^^^^^^^^^^^^^^^^^^^^^^^^^^^^^^^^^^^^^^^^^^^^^
  File "/home/airflow/.local/lib/python3.12/site-packages/airflow/models/baseoperator.py", line 400, in wrapper
    return func(self, *args, **kwargs)
           ^^^^^^^^^^^^^^^^^^^^^^^^^^^
  File "/home/airflow/.local/lib/python3.12/site-packages/airflow/providers/google/cloud/operators/bigquery.py", line 2891, in execute
    job.result(timeout=self.result_timeout, retry=self.result_retry)
  File "/home/airflow/.local/lib/python3.12/site-packages/google/cloud/bigquery/job/query.py", line 1626, in result
    while not is_job_done():
              ^^^^^^^^^^^^^
  File "/home/airflow/.local/lib/python3.12/site-packages/google/cloud/bigquery/job/query.py", line 1577, in is_job_done
    raise job_failed_exception
google.api_core.exceptions.BadRequest: 400 Unrecognized name: customerID at [3:1]; reason: invalidQuery, location: query, message: Unrecognized name: customerID at [3:1]

Location: US
Job ID: airflow_oltp_to_olap_all_transform_load_dim_customer_2024_05_28T04_58_24_100726_00_00_9bf3a521e19fa6f1fcfd01aa42cddc81

[2024-05-28T04:58:52.048+0000] {taskinstance.py:1206} INFO - Marking task as FAILED. dag_id=oltp_to_olap_all_transform, task_id=load_dim_customer, run_id=manual__2024-05-28T04:58:24.100726+00:00, execution_date=20240528T045824, start_date=20240528T045849, end_date=20240528T045852
[2024-05-28T04:58:52.120+0000] {standard_task_runner.py:110} ERROR - Failed to execute job 128 for task load_dim_customer (400 Unrecognized name: customerID at [3:1]; reason: invalidQuery, location: query, message: Unrecognized name: customerID at [3:1]

Location: US
Job ID: airflow_oltp_to_olap_all_transform_load_dim_customer_2024_05_28T04_58_24_100726_00_00_9bf3a521e19fa6f1fcfd01aa42cddc81
; 331)
[2024-05-28T04:58:52.165+0000] {local_task_job_runner.py:240} INFO - Task exited with return code 1
[2024-05-28T04:58:52.202+0000] {taskinstance.py:3498} INFO - 0 downstream tasks scheduled from follow-on schedule check
[2024-05-28T04:58:52.206+0000] {local_task_job_runner.py:222} INFO - ::endgroup::
