[2024-05-27T15:03:23.060+0000] {local_task_job_runner.py:120} INFO - ::group::Pre task execution logs
[2024-05-27T15:03:23.107+0000] {taskinstance.py:2076} INFO - Dependencies all met for dep_context=non-requeueable deps ti=<TaskInstance: bigquery_example.438 manual__2024-05-27T15:02:26.805193+00:00 [queued]>
[2024-05-27T15:03:23.137+0000] {taskinstance.py:2076} INFO - Dependencies all met for dep_context=requeueable deps ti=<TaskInstance: bigquery_example.438 manual__2024-05-27T15:02:26.805193+00:00 [queued]>
[2024-05-27T15:03:23.139+0000] {taskinstance.py:2306} INFO - Starting attempt 1 of 2
[2024-05-27T15:03:23.189+0000] {taskinstance.py:2330} INFO - Executing <Task(BigQueryInsertJobOperator): 438> on 2024-05-27 15:02:26.805193+00:00
[2024-05-27T15:03:23.224+0000] {warnings.py:110} WARNING - /home/***/.local/lib/python3.12/site-packages/***/task/task_runner/standard_task_runner.py:61: DeprecationWarning: This process (pid=510) is multi-threaded, use of fork() may lead to deadlocks in the child.
  pid = os.fork()

[2024-05-27T15:03:23.237+0000] {standard_task_runner.py:63} INFO - Started process 512 to run task
[2024-05-27T15:03:23.242+0000] {standard_task_runner.py:90} INFO - Running: ['***', 'tasks', 'run', 'bigquery_example', '438', 'manual__2024-05-27T15:02:26.805193+00:00', '--job-id', '71', '--raw', '--subdir', 'DAGS_FOLDER/bigquerry_example.py', '--cfg-path', '/tmp/tmp0r0rta5f']
[2024-05-27T15:03:23.248+0000] {standard_task_runner.py:91} INFO - Job 71: Subtask 438
[2024-05-27T15:03:23.371+0000] {task_command.py:426} INFO - Running <TaskInstance: bigquery_example.438 manual__2024-05-27T15:02:26.805193+00:00 [running]> on host 9b03efc10d80
[2024-05-27T15:03:23.716+0000] {taskinstance.py:2648} INFO - Exporting env vars: AIRFLOW_CTX_DAG_OWNER='nquynh' AIRFLOW_CTX_DAG_ID='bigquery_example' AIRFLOW_CTX_TASK_ID='438' AIRFLOW_CTX_EXECUTION_DATE='2024-05-27T15:02:26.805193+00:00' AIRFLOW_CTX_TRY_NUMBER='1' AIRFLOW_CTX_DAG_RUN_ID='manual__2024-05-27T15:02:26.805193+00:00'
[2024-05-27T15:03:23.724+0000] {taskinstance.py:430} INFO - ::endgroup::
[2024-05-27T15:03:23.842+0000] {connection.py:274} WARNING - Connection schemes (type: google_cloud_platform) shall not contain '_' according to RFC3986.
[2024-05-27T15:03:23.856+0000] {base.py:84} INFO - Using connection ID 'google_cloud_default' for task execution.
[2024-05-27T15:03:24.146+0000] {bigquery.py:2832} INFO - Executing: {'query': {'query': ' \n                        INSERT INTO `datawarehouse-423912.1.categories`\n                        VALUES (3, "quynh")\n                    ', 'useLegacySql': False}}'
[2024-05-27T15:03:24.159+0000] {bigquery.py:1660} INFO - Inserting job ***_bigquery_example_438_2024_05_27T15_02_26_805193_00_00_0fa3d576143f4465a0c565aa892b5dce
[2024-05-27T15:03:26.000+0000] {taskinstance.py:441} INFO - ::group::Post task execution logs
[2024-05-27T15:03:26.018+0000] {taskinstance.py:2905} ERROR - Task failed with exception
Traceback (most recent call last):
  File "/home/airflow/.local/lib/python3.12/site-packages/airflow/models/taskinstance.py", line 465, in _execute_task
    result = _execute_callable(context=context, **execute_callable_kwargs)
             ^^^^^^^^^^^^^^^^^^^^^^^^^^^^^^^^^^^^^^^^^^^^^^^^^^^^^^^^^^^^^
  File "/home/airflow/.local/lib/python3.12/site-packages/airflow/models/taskinstance.py", line 432, in _execute_callable
    return execute_callable(context=context, **execute_callable_kwargs)
           ^^^^^^^^^^^^^^^^^^^^^^^^^^^^^^^^^^^^^^^^^^^^^^^^^^^^^^^^^^^^
  File "/home/airflow/.local/lib/python3.12/site-packages/airflow/models/baseoperator.py", line 400, in wrapper
    return func(self, *args, **kwargs)
           ^^^^^^^^^^^^^^^^^^^^^^^^^^^
  File "/home/airflow/.local/lib/python3.12/site-packages/airflow/providers/google/cloud/operators/bigquery.py", line 2891, in execute
    job.result(timeout=self.result_timeout, retry=self.result_retry)
  File "/home/airflow/.local/lib/python3.12/site-packages/google/cloud/bigquery/job/query.py", line 1626, in result
    while not is_job_done():
              ^^^^^^^^^^^^^
  File "/home/airflow/.local/lib/python3.12/site-packages/google/cloud/bigquery/job/query.py", line 1577, in is_job_done
    raise job_failed_exception
google.api_core.exceptions.NotFound: 404 Not found: Dataset datawarehouse-423912:1 was not found in location US; reason: notFound, message: Not found: Dataset datawarehouse-423912:1 was not found in location US

Location: US
Job ID: airflow_bigquery_example_438_2024_05_27T15_02_26_805193_00_00_0fa3d576143f4465a0c565aa892b5dce

[2024-05-27T15:03:26.065+0000] {taskinstance.py:1206} INFO - Marking task as UP_FOR_RETRY. dag_id=bigquery_example, task_id=438, run_id=manual__2024-05-27T15:02:26.805193+00:00, execution_date=20240527T150226, start_date=20240527T150323, end_date=20240527T150326
[2024-05-27T15:03:26.115+0000] {standard_task_runner.py:110} ERROR - Failed to execute job 71 for task 438 (404 Not found: Dataset datawarehouse-423912:1 was not found in location US; reason: notFound, message: Not found: Dataset datawarehouse-423912:1 was not found in location US

Location: US
Job ID: airflow_bigquery_example_438_2024_05_27T15_02_26_805193_00_00_0fa3d576143f4465a0c565aa892b5dce
; 512)
[2024-05-27T15:03:26.197+0000] {local_task_job_runner.py:240} INFO - Task exited with return code 1
[2024-05-27T15:03:26.273+0000] {taskinstance.py:3498} INFO - 0 downstream tasks scheduled from follow-on schedule check
[2024-05-27T15:03:26.290+0000] {local_task_job_runner.py:222} INFO - ::endgroup::
