[2024-05-27T15:10:14.597+0000] {local_task_job_runner.py:120} INFO - ::group::Pre task execution logs
[2024-05-27T15:10:14.657+0000] {taskinstance.py:2076} INFO - Dependencies all met for dep_context=non-requeueable deps ti=<TaskInstance: bigquery_example.438 manual__2024-05-27T15:02:26.805193+00:00 [queued]>
[2024-05-27T15:10:14.686+0000] {taskinstance.py:2076} INFO - Dependencies all met for dep_context=requeueable deps ti=<TaskInstance: bigquery_example.438 manual__2024-05-27T15:02:26.805193+00:00 [queued]>
[2024-05-27T15:10:14.688+0000] {taskinstance.py:2306} INFO - Starting attempt 2 of 2
[2024-05-27T15:10:14.729+0000] {taskinstance.py:2330} INFO - Executing <Task(BigQueryInsertJobOperator): 438> on 2024-05-27 15:02:26.805193+00:00
[2024-05-27T15:10:14.770+0000] {warnings.py:110} WARNING - /home/***/.local/lib/python3.12/site-packages/***/task/task_runner/standard_task_runner.py:61: DeprecationWarning: This process (pid=55) is multi-threaded, use of fork() may lead to deadlocks in the child.
  pid = os.fork()

[2024-05-27T15:10:14.778+0000] {standard_task_runner.py:63} INFO - Started process 57 to run task
[2024-05-27T15:10:14.779+0000] {standard_task_runner.py:90} INFO - Running: ['***', 'tasks', 'run', 'bigquery_example', '438', 'manual__2024-05-27T15:02:26.805193+00:00', '--job-id', '74', '--raw', '--subdir', 'DAGS_FOLDER/bigquerry_example.py', '--cfg-path', '/tmp/tmppi9666jc']
[2024-05-27T15:10:14.791+0000] {standard_task_runner.py:91} INFO - Job 74: Subtask 438
[2024-05-27T15:10:14.943+0000] {task_command.py:426} INFO - Running <TaskInstance: bigquery_example.438 manual__2024-05-27T15:02:26.805193+00:00 [running]> on host 9b03efc10d80
[2024-05-27T15:10:15.179+0000] {taskinstance.py:2648} INFO - Exporting env vars: AIRFLOW_CTX_DAG_OWNER='nquynh' AIRFLOW_CTX_DAG_ID='bigquery_example' AIRFLOW_CTX_TASK_ID='438' AIRFLOW_CTX_EXECUTION_DATE='2024-05-27T15:02:26.805193+00:00' AIRFLOW_CTX_TRY_NUMBER='2' AIRFLOW_CTX_DAG_RUN_ID='manual__2024-05-27T15:02:26.805193+00:00'
[2024-05-27T15:10:15.182+0000] {taskinstance.py:430} INFO - ::endgroup::
[2024-05-27T15:10:15.248+0000] {connection.py:274} WARNING - Connection schemes (type: google_cloud_platform) shall not contain '_' according to RFC3986.
[2024-05-27T15:10:15.254+0000] {base.py:84} INFO - Using connection ID 'google_cloud_default' for task execution.
[2024-05-27T15:10:15.408+0000] {bigquery.py:2832} INFO - Executing: {'query': {'query': ' \n                        INSERT INTO `datawarehouse-423912.1.categories`\n                        VALUES (3, "quynh")\n                    ', 'useLegacySql': False}}'
[2024-05-27T15:10:15.411+0000] {bigquery.py:1660} INFO - Inserting job ***_bigquery_example_438_2024_05_27T15_02_26_805193_00_00_fa90cc3266affee9fc771042984878b5
[2024-05-27T15:10:16.800+0000] {taskinstance.py:441} INFO - ::group::Post task execution logs
[2024-05-27T15:10:16.802+0000] {taskinstance.py:2905} ERROR - Task failed with exception
Traceback (most recent call last):
  File "/home/airflow/.local/lib/python3.12/site-packages/airflow/models/taskinstance.py", line 465, in _execute_task
    result = _execute_callable(context=context, **execute_callable_kwargs)
             ^^^^^^^^^^^^^^^^^^^^^^^^^^^^^^^^^^^^^^^^^^^^^^^^^^^^^^^^^^^^^
  File "/home/airflow/.local/lib/python3.12/site-packages/airflow/models/taskinstance.py", line 432, in _execute_callable
    return execute_callable(context=context, **execute_callable_kwargs)
           ^^^^^^^^^^^^^^^^^^^^^^^^^^^^^^^^^^^^^^^^^^^^^^^^^^^^^^^^^^^^
  File "/home/airflow/.local/lib/python3.12/site-packages/airflow/models/baseoperator.py", line 400, in wrapper
    return func(self, *args, **kwargs)
           ^^^^^^^^^^^^^^^^^^^^^^^^^^^
  File "/home/airflow/.local/lib/python3.12/site-packages/airflow/providers/google/cloud/operators/bigquery.py", line 2891, in execute
    job.result(timeout=self.result_timeout, retry=self.result_retry)
  File "/home/airflow/.local/lib/python3.12/site-packages/google/cloud/bigquery/job/query.py", line 1626, in result
    while not is_job_done():
              ^^^^^^^^^^^^^
  File "/home/airflow/.local/lib/python3.12/site-packages/google/cloud/bigquery/job/query.py", line 1577, in is_job_done
    raise job_failed_exception
google.api_core.exceptions.NotFound: 404 Not found: Dataset datawarehouse-423912:1 was not found in location US; reason: notFound, message: Not found: Dataset datawarehouse-423912:1 was not found in location US

Location: US
Job ID: airflow_bigquery_example_438_2024_05_27T15_02_26_805193_00_00_fa90cc3266affee9fc771042984878b5

[2024-05-27T15:10:16.842+0000] {taskinstance.py:1206} INFO - Marking task as FAILED. dag_id=bigquery_example, task_id=438, run_id=manual__2024-05-27T15:02:26.805193+00:00, execution_date=20240527T150226, start_date=20240527T151014, end_date=20240527T151016
[2024-05-27T15:10:16.869+0000] {standard_task_runner.py:110} ERROR - Failed to execute job 74 for task 438 (404 Not found: Dataset datawarehouse-423912:1 was not found in location US; reason: notFound, message: Not found: Dataset datawarehouse-423912:1 was not found in location US

Location: US
Job ID: airflow_bigquery_example_438_2024_05_27T15_02_26_805193_00_00_fa90cc3266affee9fc771042984878b5
; 57)
[2024-05-27T15:10:16.894+0000] {local_task_job_runner.py:240} INFO - Task exited with return code 1
[2024-05-27T15:10:16.929+0000] {taskinstance.py:3498} INFO - 0 downstream tasks scheduled from follow-on schedule check
[2024-05-27T15:10:16.935+0000] {local_task_job_runner.py:222} INFO - ::endgroup::
