[2024-05-27T15:19:08.913+0000] {task_context_logger.py:104} WARNING - Marking task instance <TaskInstance: bigquery_example.438 manual__2024-05-27T15:02:24.659803+00:00 [queued]> stuck in queued as failed. If the task instance has available retries, it will be retried.
[2024-05-27T15:19:11.034+0000] {task_context_logger.py:104} ERROR - Executor reports task instance <TaskInstance: bigquery_example.438 manual__2024-05-27T15:02:24.659803+00:00 [queued]> finished (failed) although the task says it's queued. (Info: None) Was the task killed externally?
