[2024-05-27T15:03:15.855+0000] {task_context_logger.py:104} ERROR - Executor reports task instance <TaskInstance: bigquery_example.438 manual__2024-05-27T15:02:24.659803+00:00 [queued]> finished (failed) although the task says it's queued. (Info: None) Was the task killed externally?
