[2024-05-26T17:47:47.084+0000] {task_context_logger.py:104} ERROR - Executor reports task instance <TaskInstance: bigquery_example.run_bigquery_query manual__2024-05-26T17:47:37.190623+00:00 [queued]> finished (failed) although the task says it's queued. (Info: None) Was the task killed externally?
