[2024-05-28T13:14:01.431+0000] {local_task_job_runner.py:120} INFO - ::group::Pre task execution logs
[2024-05-28T13:14:01.456+0000] {taskinstance.py:2076} INFO - Dependencies all met for dep_context=non-requeueable deps ti=<TaskInstance: loading_to_bigquerry.update_customer manual__2024-05-28T13:11:45.617626+00:00 [queued]>
[2024-05-28T13:14:01.469+0000] {taskinstance.py:2076} INFO - Dependencies all met for dep_context=requeueable deps ti=<TaskInstance: loading_to_bigquerry.update_customer manual__2024-05-28T13:11:45.617626+00:00 [queued]>
[2024-05-28T13:14:01.471+0000] {taskinstance.py:2306} INFO - Starting attempt 1 of 0
[2024-05-28T13:14:01.491+0000] {taskinstance.py:2330} INFO - Executing <Task(BigQueryInsertJobOperator): update_customer> on 2024-05-28 13:11:45.617626+00:00
[2024-05-28T13:14:01.503+0000] {warnings.py:110} WARNING - /home/***/.local/lib/python3.12/site-packages/***/task/task_runner/standard_task_runner.py:61: DeprecationWarning: This process (pid=2572) is multi-threaded, use of fork() may lead to deadlocks in the child.
  pid = os.fork()

[2024-05-28T13:14:01.505+0000] {standard_task_runner.py:63} INFO - Started process 2582 to run task
[2024-05-28T13:14:01.506+0000] {standard_task_runner.py:90} INFO - Running: ['***', 'tasks', 'run', 'loading_to_bigquerry', 'update_customer', 'manual__2024-05-28T13:11:45.617626+00:00', '--job-id', '373', '--raw', '--subdir', 'DAGS_FOLDER/load_to_bigquerry.py', '--cfg-path', '/tmp/tmpy0iowdbw']
[2024-05-28T13:14:01.509+0000] {standard_task_runner.py:91} INFO - Job 373: Subtask update_customer
[2024-05-28T13:14:01.588+0000] {task_command.py:426} INFO - Running <TaskInstance: loading_to_bigquerry.update_customer manual__2024-05-28T13:11:45.617626+00:00 [running]> on host 9b03efc10d80
[2024-05-28T13:14:01.789+0000] {taskinstance.py:2648} INFO - Exporting env vars: AIRFLOW_CTX_DAG_OWNER='ngquynh' AIRFLOW_CTX_DAG_ID='loading_to_bigquerry' AIRFLOW_CTX_TASK_ID='update_customer' AIRFLOW_CTX_EXECUTION_DATE='2024-05-28T13:11:45.617626+00:00' AIRFLOW_CTX_TRY_NUMBER='1' AIRFLOW_CTX_DAG_RUN_ID='manual__2024-05-28T13:11:45.617626+00:00'
[2024-05-28T13:14:01.793+0000] {taskinstance.py:430} INFO - ::endgroup::
[2024-05-28T13:14:01.840+0000] {connection.py:274} WARNING - Connection schemes (type: google_cloud_platform) shall not contain '_' according to RFC3986.
[2024-05-28T13:14:01.847+0000] {base.py:84} INFO - Using connection ID 'google_cloud_default' for task execution.
[2024-05-28T13:14:02.001+0000] {bigquery.py:2832} INFO - Executing: {'query': {'query': '-- quá trình upload dataset lên bogquerry, header của mỗi cột bị sai thành field 0_1_2... nên cần query để đổi lại tên cho mỗi header\ncreate or replace table `datawarehouse-423912.warehouse.newupdated_customers`\nas \nselect string_field_0 as customerID,\nstring_field_1 as companyName,\nstring_field_2 as contactName,\nstring_field_3 as contactTitle,\nstring_field_4 as address,\nstring_field_5 as city,\nstring_field_6 as region,\nstring_field_7 as postalCode,\nstring_field_8 as country,\nstring_field_9 as phone,\nstring_field_10 as fax\nfrom `datawarehouse-423912.warehouse.customers`\n', 'useLegacySql': False}}'
[2024-05-28T13:14:02.003+0000] {bigquery.py:1660} INFO - Inserting job ***_loading_to_bigquerry_update_customer_2024_05_28T13_11_45_617626_00_00_bd68203f79c7ab403d7b7f9a96bb01c9
[2024-05-28T13:14:04.571+0000] {taskinstance.py:441} INFO - ::group::Post task execution logs
[2024-05-28T13:14:04.572+0000] {taskinstance.py:2905} ERROR - Task failed with exception
Traceback (most recent call last):
  File "/home/airflow/.local/lib/python3.12/site-packages/airflow/models/taskinstance.py", line 465, in _execute_task
    result = _execute_callable(context=context, **execute_callable_kwargs)
             ^^^^^^^^^^^^^^^^^^^^^^^^^^^^^^^^^^^^^^^^^^^^^^^^^^^^^^^^^^^^^
  File "/home/airflow/.local/lib/python3.12/site-packages/airflow/models/taskinstance.py", line 432, in _execute_callable
    return execute_callable(context=context, **execute_callable_kwargs)
           ^^^^^^^^^^^^^^^^^^^^^^^^^^^^^^^^^^^^^^^^^^^^^^^^^^^^^^^^^^^^
  File "/home/airflow/.local/lib/python3.12/site-packages/airflow/models/baseoperator.py", line 400, in wrapper
    return func(self, *args, **kwargs)
           ^^^^^^^^^^^^^^^^^^^^^^^^^^^
  File "/home/airflow/.local/lib/python3.12/site-packages/airflow/providers/google/cloud/operators/bigquery.py", line 2891, in execute
    job.result(timeout=self.result_timeout, retry=self.result_retry)
  File "/home/airflow/.local/lib/python3.12/site-packages/google/cloud/bigquery/job/query.py", line 1626, in result
    while not is_job_done():
              ^^^^^^^^^^^^^
  File "/home/airflow/.local/lib/python3.12/site-packages/google/cloud/bigquery/job/query.py", line 1577, in is_job_done
    raise job_failed_exception
google.api_core.exceptions.BadRequest: 400 Unrecognized name: string_field_0 at [4:8]; reason: invalidQuery, location: query, message: Unrecognized name: string_field_0 at [4:8]

Location: US
Job ID: airflow_loading_to_bigquerry_update_customer_2024_05_28T13_11_45_617626_00_00_bd68203f79c7ab403d7b7f9a96bb01c9

[2024-05-28T13:14:04.588+0000] {taskinstance.py:1206} INFO - Marking task as FAILED. dag_id=loading_to_bigquerry, task_id=update_customer, run_id=manual__2024-05-28T13:11:45.617626+00:00, execution_date=20240528T131145, start_date=20240528T131401, end_date=20240528T131404
[2024-05-28T13:14:04.611+0000] {standard_task_runner.py:110} ERROR - Failed to execute job 373 for task update_customer (400 Unrecognized name: string_field_0 at [4:8]; reason: invalidQuery, location: query, message: Unrecognized name: string_field_0 at [4:8]

Location: US
Job ID: airflow_loading_to_bigquerry_update_customer_2024_05_28T13_11_45_617626_00_00_bd68203f79c7ab403d7b7f9a96bb01c9
; 2582)
[2024-05-28T13:14:04.653+0000] {local_task_job_runner.py:240} INFO - Task exited with return code 1
[2024-05-28T13:14:04.676+0000] {taskinstance.py:3498} INFO - 0 downstream tasks scheduled from follow-on schedule check
[2024-05-28T13:14:04.680+0000] {local_task_job_runner.py:222} INFO - ::endgroup::
